Workbook

Sheet Ben benchmark
A4: Model | B4: Overall MSE | C4: Overall MAE | D4: Complex MSE | E4: Complex MAE | F4: Stable MSE | G4: Stable MAE | H4: Oscillatory MSE | I4: Oscillatory MAE | J4: Monotonic MSE | K4: Monotonic MAE
A5: Point Forecasting
A6: DLinear | B6: 0.0591 | C6: 0.1702 | D6: 0.0687 | E6: 0.1767 | F6: 0.0426 | G6: 0.149 | H6: 0.1801 | I6: 0.3135 | J6: 0.0509 | K6: 0.1813
A7: iTransformer | B7: 0.025 | C7: 0.0691 | D7: 0.0204 | E7: 0.0593 | F7: 0.0181 | G7: 0.0544 | H7: 0.1067 | I7: 0.2138 | J7: 0.0185 | K7: 0.0764
A8: PatchTST | B8: 0.0264 | C8: 0.0722 | D8: 0.0207 | E8: 0.0617 | F8: 0.0186 | G8: 0.0558 | H8: 0.1242 | I8: 0.2377 | J8: 0.0167 | K8: 0.0764
A9: TimeMixer | B9: 0.0545 | C9: 0.1516 | D9: 0.0414 | E9: 0.1138 | F9: 0.0499 | G9: 0.1463 | H9: 0.1135 | I9: 0.2374 | J9: 0.0696 | K9: 0.2072
A10: TimeXer | B10: 0.0199 | C10: 0.0619 | D10: 0.0158 | E10: 0.0493 | F10: 0.0131 | G10: 0.0476 | H10: 0.0974 | I10: 0.2043 | J10: 0.0152 | K10: 0.0756
A11: SMamba | B11: 0.0325 | C11: 0.0861 | D11: 0.0335 | E11: 0.0814 | F11: 0.023 | G11: 0.0673 | H11: 0.1152 | I11: 0.2249 | J11: 0.0293 | K11: 0.1117
A12: BiMamba4TS | B12: 0.027 | C12: 0.0742 | D12: 0.0218 | E12: 0.0633 | F12: 0.0195 | G12: 0.0578 | H12: 0.1139 | I12: 0.2297 | J12: 0.0222 | K12: 0.0865
A13: NSFormer | B13: 0.0158 | C13: 0.0581 | D13: 0.013 | E13: 0.0497 | F13: 0.0097 | G13: 0.0453 | H13: 0.09 | I13: 0.2075 | J13: 0.0059 | K13: 0.0472
A14: Probabilistic Forecasting w/o Regime Condition
A15: CSDI | B15: 0.0717 | C15: 0.1878 | D15: 0.0512 | E15: 0.1518 | F15: 0.0716 | G15: 0.1886 | H15: 0.1385 | I15: 0.2859 | J15: 0.071 | K15: 0.1934
A16: TSDiff | B16: 0.0879 | C16: 0.1607 | D16: 0.0838 | E16: 0.1472 | F16: 0.082 | G16: 0.148 | H16: 0.1635 | I16: 0.2797 | J16: 0.0793 | K16: 0.1826
A17: TSFlow | B17: 0.027 | C17: 0.0663 | D17: 0.0248 | E17: 0.062 | F17: 0.0172 | G17: 0.0486 | H17: 0.1409 | I17: 0.2525 | J17: 0.0106 | K17: 0.05
A18: Ours | B18: 0.0207 | C18: 0.0715 | D18: 0.0198 | E18: 0.0741 | F18: 0.0126 | G18: 0.0535 | H18: 0.1118 | I18: 0.2504 | J18: 0.0068 | K18: 0.047
A19: Probabilistic Forecasting w/ Regime Condition
A20: CSDI† | B20: 0.0569 | C20: 0.1719 | D20: 0.051 | E20: 0.1446 | F20: 0.0557 | G20: 0.175 | H20: 0.0948 | I20: 0.2326 | J20: 0.0509 | K20: 0.1712
A21: TSDiff† | B21: 0.0588 | C21: 0.1485 | D21: 0.0691 | E21: 0.133 | F21: 0.0378 | G21: 0.1277 | H21: 0.2141 | I21: 0.3413 | J21: 0.0511 | K21: 0.1717
A22: TSFlow† | B22: 0.0153 | C22: 0.055 | D22: 0.0221 | E22: 0.0611 | F22: 0.0077 | G22: 0.0405 | H22: 0.0721 | I22: 0.1757 | J22: 0.0054 | K22: 0.043
A23: Ours† | B23: 0.0106 | C23: 0.047 | D23: 0.0288 | E23: 0.0919 | F23: 0.0052 | G23: 0.0307 | H23: 0.039 | I23: 0.1321 | J23: 0.0037 | K23: 0.0335
D46: ======================================================================================================================== -> #ERROR!
D47: FINAL COMBINED STRATIFIED BENCHMARK PERFORMANCE (TABLE 1 REPRODUCTION)
D48: ======================================================================================================================== -> #ERROR!
D49: | Model | Overall MSE | Overall MAE | Complex MSE | Complex MAE | Stable MSE | Stable MAE | Oscillatory MSE | Oscillatory MAE | Monotonic MSE | Monotonic MAE |
D50: | -------------------------------------------------- | ------------ | ------------ | ------------ | ------------ | ------------ | ------------ | --------------- | --------------- | ------------- | ------------- |
D51: | **Point Forecasting** | | | | | | | | | | |
D52: | DLinear | 0.0591±0.000 | 0.1702±0.000 | 0.0687±0.000 | 0.1767±0.000 | 0.0426±0.000 | 0.1490±0.000 | 0.1801±0.000 | 0.3135±0.000 | 0.0509±0.000 | 0.1813±0.000 |
D53: | iTransformer | 0.0250±0.000 | 0.0691±0.000 | 0.0204±0.000 | 0.0593±0.000 | 0.0181±0.000 | 0.0544±0.000 | 0.1067±0.000 | 0.2138±0.000 | 0.0185±0.000 | 0.0764±0.000 |
D54: | PatchTST | 0.0264±0.000 | 0.0722±0.000 | 0.0207±0.000 | 0.0617±0.000 | 0.0186±0.000 | 0.0558±0.000 | 0.1242±0.000 | 0.2377±0.000 | 0.0167±0.000 | 0.0764±0.000 |
D55: | TimeMixer | 0.0545±0.000 | 0.1516±0.000 | 0.0414±0.000 | 0.1138±0.000 | 0.0499±0.000 | 0.1463±0.000 | 0.1135±0.000 | 0.2374±0.000 | 0.0696±0.000 | 0.2072±0.000 |
D56: | TimeXer | 0.0199±0.000 | 0.0619±0.000 | 0.0158±0.000 | 0.0493±0.000 | 0.0131±0.000 | 0.0476±0.000 | 0.0974±0.000 | 0.2043±0.000 | 0.0152±0.000 | 0.0756±0.000 |
D57: | SMamba | 0.0325±0.000 | 0.0861±0.000 | 0.0335±0.000 | 0.0814±0.000 | 0.0230±0.000 | 0.0673±0.000 | 0.1152±0.000 | 0.2249±0.000 | 0.0293±0.000 | 0.1117±0.000 |
D58: | BiMamba4TS | 0.0270±0.000 | 0.0742±0.000 | 0.0218±0.000 | 0.0633±0.000 | 0.0195±0.000 | 0.0578±0.000 | 0.1139±0.000 | 0.2297±0.000 | 0.0222±0.000 | 0.0865±0.000 |
D59: | NSFormer | 0.0158±0.000 | 0.0581±0.000 | 0.0130±0.000 | 0.0497±0.000 | 0.0097±0.000 | 0.0453±0.000 | 0.0900±0.000 | 0.2075±0.000 | 0.0059±0.000 | 0.0472±0.000 |
D60: | Chronos | 0.1615±0.000 | 0.1762±0.000 | 0.4115±0.000 | 0.1957±0.000 | 0.0746±0.000 | 0.1539±0.000 | 0.2610±0.000 | 0.3340±0.000 | 0.0529±0.000 | 0.1551±0.000 |
... D70: | Ours† | 0.0095±0.000 | 0.0461±0.000 | 0.0150±0.000 | 0.0635±0.000 | 0.0049±0.000 | 0.0315±0.000 | 0.0401±0.000 | 0.1340±0.000 | 0.0033±0.000 | 0.0324±0.000 |

Sheet Old copy of Ben benchmark
A4: Model | B4: Overall MSE | C4: Overall MAE | D4: Complex MSE | E4: Complex MAE | F4: Stable MSE | G4: Stable MAE | H4: Oscillatory MSE | I4: Oscillatory MAE | J4: Monotonic MSE | K4: Monotonic MAE
A5: Point Forecasting
A6: DLinear | B6: 0.0591 | C6: 0.1702 | D6: 0.0687 | E6: 0.1767 | F6: 0.0426 | G6: 0.149 | H6: 0.1801 | I6: 0.3135 | J6: 0.0509 | K6: 0.1813
A7: iTransformer | B7: 0.025 | C7: 0.0691 | D7: 0.0204 | E7: 0.0593 | F7: 0.0181 | G7: 0.0544 | H7: 0.1067 | I7: 0.2138 | J7: 0.0185 | K7: 0.0764
A8: PatchTST | B8: 0.0264 | C8: 0.0722 | D8: 0.0207 | E8: 0.0617 | F8: 0.0186 | G8: 0.0558 | H8: 0.1242 | I8: 0.2377 | J8: 0.0167 | K8: 0.0764
A9: TimeMixer | B9: 0.0545 | C9: 0.1516 | D9: 0.0414 | E9: 0.1138 | F9: 0.0499 | G9: 0.1463 | H9: 0.1135 | I9: 0.2374 | J9: 0.0696 | K9: 0.2072
A10: TimeXer | B10: 0.0199 | C10: 0.0619 | D10: 0.0158 | E10: 0.0493 | F10: 0.0131 | G10: 0.0476 | H10: 0.0974 | I10: 0.2043 | J10: 0.0152 | K10: 0.0756
A11: SMamba | B11: 0.0325 | C11: 0.0861 | D11: 0.0335 | E11: 0.0814 | F11: 0.023 | G11: 0.0673 | H11: 0.1152 | I11: 0.2249 | J11: 0.0293 | K11: 0.1117
A12: BiMamba4TS | B12: 0.027 | C12: 0.0742 | D12: 0.0218 | E12: 0.0633 | F12: 0.0195 | G12: 0.0578 | H12: 0.1139 | I12: 0.2297 | J12: 0.0222 | K12: 0.0865
A13: NSFormer | B13: 0.0158 | C13: 0.0581 | D13: 0.013 | E13: 0.0497 | F13: 0.0097 | G13: 0.0453 | H13: 0.09 | I13: 0.2075 | J13: 0.0059 | K13: 0.0472
A14: Probabilistic Forecasting w/o Regime Condition
A15: CSDI | B15: 0.0717 | C15: 0.1878 | D15: 0.0512 | E15: 0.1518 | F15: 0.0716 | G15: 0.1886 | H15: 0.1385 | I15: 0.2859 | J15: 0.071 | K15: 0.1934
A16: TSDiff | B16: 0.0879 | C16: 0.1607 | D16: 0.0838 | E16: 0.1472 | F16: 0.082 | G16: 0.148 | H16: 0.1635 | I16: 0.2797 | J16: 0.0793 | K16: 0.1826
A17: TSFlow | B17: 0.027 | C17: 0.0663 | D17: 0.0248 | E17: 0.062 | F17: 0.0172 | G17: 0.0486 | H17: 0.1409 | I17: 0.2525 | J17: 0.0106 | K17: 0.05
A18: Ours | B18: 0.0207 | C18: 0.0715 | D18: 0.0198 | E18: 0.0741 | F18: 0.0126 | G18: 0.0535 | H18: 0.1118 | I18: 0.2504 | J18: 0.0068 | K18: 0.047
A19: Probabilistic Forecasting w/ Regime Condition
A20: CSDI† | B20: 0.0569 | C20: 0.1719 | D20: 0.051 | E20: 0.1446 | F20: 0.0557 | G20: 0.175 | H20: 0.0948 | I20: 0.2326 | J20: 0.0509 | K20: 0.1712
A21: TSDiff† | B21: 0.0588 | C21: 0.1485 | D21: 0.0691 | E21: 0.133 | F21: 0.0378 | G21: 0.1277 | H21: 0.2141 | I21: 0.3413 | J21: 0.0511 | K21: 0.1717
A22: TSFlow† | B22: 0.0153 | C22: 0.055 | D22: 0.0221 | E22: 0.0611 | F22: 0.0077 | G22: 0.0405 | H22: 0.0721 | I22: 0.1757 | J22: 0.0054 | K22: 0.043
A23: Ours† | B23: 0.0095 | C23: 0.0461 | D23: 0.015 | E23: 0.0635 | F23: 0.0049 | G23: 0.0315 | H23: 0.0401 | I23: 0.134 | J23: 0.0033 | K23: 0.0324
A26: | Model | Overall MSE | Overall MAE | Complex MSE | Complex MAE | Stable MSE | Stable MAE | Oscillatory MSE | Oscillatory MAE | Monotonic MSE | Monotonic MAE | | C26: FINAL COMBINED STRATIFIED BENCHMARK PERFORMANCE (TABLE 1 REPRODUCTION)
A27: | -------------------------------------------------- | ------------ | ------------ | ------------ | ------------ | ------------ | ------------ | --------------- | --------------- | ------------- | ------------- |
A28: | **Point Forecasting** | | | | | | | | | | | | C28: | Model | Overall MSE | Overall MAE | Complex MSE | Complex MAE | Stable MSE | Stable MAE | Oscillatory MSE | Oscillatory MAE | Monotonic MSE | Monotonic MAE |
A29: | DLinear | 0.0591±0.000 | 0.1702±0.000 | 0.0687±0.000 | 0.1767±0.000 | 0.0426±0.000 | 0.1490±0.000 | 0.1801±0.000 | 0.3135±0.000 | 0.0509±0.000 | 0.1813±0.000 | | C29: | -------------------------------------------------- | ------------ | ------------ | ------------ | ------------ | ------------ | ------------ | --------------- | --------------- | ------------- | ------------- |
A30: | iTransformer | 0.0250±0.000 | 0.0691±0.000 | 0.0204±0.000 | 0.0593±0.000 | 0.0181±0.000 | 0.0544±0.000 | 0.1067±0.000 | 0.2138±0.000 | 0.0185±0.000 | 0.0764±0.000 | | C30: | **Point Forecasting** | | | | | | | | | | |
A31: | PatchTST | 0.0264±0.000 | 0.0722±0.000 | 0.0207±0.000 | 0.0617±0.000 | 0.0186±0.000 | 0.0558±0.000 | 0.1242±0.000 | 0.2377±0.000 | 0.0167±0.000 | 0.0764±0.000 | | C31: | DLinear | 0.0591±0.000 | 0.1702±0.000 | 0.0687±0.000 | 0.1767±0.000 | 0.0426±0.000 | 0.1490±0.000 | 0.1801±0.000 | 0.3135±0.000 | 0.0509±0.000 | 0.1813±0.000 |
A32: | TimeMixer | 0.0545±0.000 | 0.1516±0.000 | 0.0414±0.000 | 0.1138±0.000 | 0.0499±0.000 | 0.1463±0.000 | 0.1135±0.000 | 0.2374±0.000 | 0.0696±0.000 | 0.2072±0.000 | | C32: | iTransformer | 0.0250±0.000 | 0.0691±0.000 | 0.0204±0.000 | 0.0593±0.000 | 0.0181±0.000 | 0.0544±0.000 | 0.1067±0.000 | 0.2138±0.000 | 0.0185±0.000 | 0.0764±0.000 |
A33: | TimeXer | 0.0199±0.000 | 0.0619±0.000 | 0.0158±0.000 | 0.0493±0.000 | 0.0131±0.000 | 0.0476±0.000 | 0.0974±0.000 | 0.2043±0.000 | 0.0152±0.000 | 0.0756±0.000 | | C33: | PatchTST | 0.0264±0.000 | 0.0722±0.000 | 0.0207±0.000 | 0.0617±0.000 | 0.0186±0.000 | 0.0558±0.000 | 0.1242±0.000 | 0.2377±0.000 | 0.0167±0.000 | 0.0764±0.000 |
A34: | SMamba | 0.0325±0.000 | 0.0861±0.000 | 0.0335±0.000 | 0.0814±0.000 | 0.0230±0.000 | 0.0673±0.000 | 0.1152±0.000 | 0.2249±0.000 | 0.0293±0.000 | 0.1117±0.000 | | C34: | TimeMixer | 0.0545±0.000 | 0.1516±0.000 | 0.0414±0.000 | 0.1138±0.000 | 0.0499±0.000 | 0.1463±0.000 | 0.1135±0.000 | 0.2374±0.000 | 0.0696±0.000 | 0.2072±0.000 |
A35: | BiMamba4TS | 0.0270±0.000 | 0.0742±0.000 | 0.0218±0.000 | 0.0633±0.000 | 0.0195±0.000 | 0.0578±0.000 | 0.1139±0.000 | 0.2297±0.000 | 0.0222±0.000 | 0.0865±0.000 | | C35: | TimeXer | 0.0199±0.000 | 0.0619±0.000 | 0.0158±0.000 | 0.0493±0.000 | 0.0131±0.000 | 0.0476±0.000 | 0.0974±0.000 | 0.2043±0.000 | 0.0152±0.000 | 0.0756±0.000 |
A36: | NSFormer | 0.0158±0.000 | 0.0581±0.000 | 0.0130±0.000 | 0.0497±0.000 | 0.0097±0.000 | 0.0453±0.000 | 0.0900±0.000 | 0.2075±0.000 | 0.0059±0.000 | 0.0472±0.000 | | B36: | NSformer | 0.0158±0.000 | 0.0581±0.000 | 0.0158±0.000 | 0.0564±0.000 | 0.0169±0.000 | 0.0610±0.000 | 0.0166±0.000 | 0.0576±0.000 | 0.0068±0.000 | 0.0401±0.000 | | C36: | SMamba | 0.0325±0.000 | 0.0861±0.000 | 0.0335±0.000 | 0.0814±0.000 | 0.0230±0.000 | 0.0673±0.000 | 0.1152±0.000 | 0.2249±0.000 | 0.0293±0.000 | 0.1117±0.000 |
A37: | Chronos | 0.1615±0.000 | 0.1762±0.000 | 0.4115±0.000 | 0.1957±0.000 | 0.0746±0.000 | 0.1539±0.000 | 0.2610±0.000 | 0.3340±0.000 | 0.0529±0.000 | 0.1551±0.000 | | C37: | BiMamba4TS | 0.0270±0.000 | 0.0742±0.000 | 0.0218±0.000 | 0.0633±0.000 | 0.0195±0.000 | 0.0578±0.000 | 0.1139±0.000 | 0.2297±0.000 | 0.0222±0.000 | 0.0865±0.000 |
A38: | **Probabilistic Forecasting w/o Regime Condition** | | | | | | | | | | | | C38: | NSFormer | 0.0158±0.000 | 0.0581±0.000 | 0.0130±0.000 | 0.0497±0.000 | 0.0097±0.000 | 0.0453±0.000 | 0.0900±0.000 | 0.2075±0.000 | 0.0059±0.000 | 0.0472±0.000 |
A39: | CSDI | 0.0717±0.000 | 0.1878±0.000 | 0.0512±0.000 | 0.1518±0.000 | 0.0716±0.000 | 0.1886±0.000 | 0.1385±0.000 | 0.2859±0.000 | 0.0710±0.000 | 0.1934±0.000 | | C39: | Chronos | 0.1615±0.000 | 0.1762±0.000 | 0.4115±0.000 | 0.1957±0.000 | 0.0746±0.000 | 0.1539±0.000 | 0.2610±0.000 | 0.3340±0.000 | 0.0529±0.000 | 0.1551±0.000 |
A40: | TSDiff | 0.0879±0.000 | 0.1607±0.000 | 0.0838±0.000 | 0.1472±0.000 | 0.0820±0.000 | 0.1480±0.000 | 0.1635±0.000 | 0.2797±0.000 | 0.0793±0.000 | 0.1826±0.000 | | C40: | **Probabilistic Forecasting w/o Regime Condition** | | | | | | | | | | |
A41: | TSFlow | 0.0270±0.000 | 0.0663±0.000 | 0.0248±0.000 | 0.0620±0.000 | 0.0172±0.000 | 0.0486±0.000 | 0.1409±0.000 | 0.2525±0.000 | 0.0106±0.000 | 0.0500±0.000 | | C41: | CSDI | 0.0717±0.000 | 0.1878±0.000 | 0.0512±0.000 | 0.1518±0.000 | 0.0716±0.000 | 0.1886±0.000 | 0.1385±0.000 | 0.2859±0.000 | 0.0710±0.000 | 0.1934±0.000 |
A42: | Ours | 0.0207±0.000 | 0.0715±0.000 | 0.0198±0.000 | 0.0741±0.000 | 0.0126±0.000 | 0.0535±0.000 | 0.1118±0.000 | 0.2504±0.000 | 0.0068±0.000 | 0.0470±0.000 | | C42: | TSDiff | 0.0879±0.000 | 0.1607±0.000 | 0.0838±0.000 | 0.1472±0.000 | 0.0820±0.000 | 0.1480±0.000 | 0.1635±0.000 | 0.2797±0.000 | 0.0793±0.000 | 0.1826±0.000 |
A43: | **Probabilistic Forecasting w/ Regime Condition** | | | | | | | | | | | | C43: | TSFlow | 0.0270±0.000 | 0.0663±0.000 | 0.0248±0.000 | 0.0620±0.000 | 0.0172±0.000 | 0.0486±0.000 | 0.1409±0.000 | 0.2525±0.000 | 0.0106±0.000 | 0.0500±0.000 |
A44: | CSDI† | 0.0569±0.000 | 0.1719±0.000 | 0.0510±0.000 | 0.1446±0.000 | 0.0557±0.000 | 0.1750±0.000 | 0.0948±0.000 | 0.2326±0.000 | 0.0509±0.000 | 0.1712±0.000 | | C44: | Ours | 0.0207±0.000 | 0.0715±0.000 | 0.0198±0.000 | 0.0741±0.000 | 0.0126±0.000 | 0.0535±0.000 | 0.1118±0.000 | 0.2504±0.000 | 0.0068±0.000 | 0.0470±0.000 |
A45: | TSDiff† | 0.0588±0.000 | 0.1485±0.000 | 0.0691±0.000 | 0.1330±0.000 | 0.0378±0.000 | 0.1277±0.000 | 0.2141±0.000 | 0.3413±0.000 | 0.0511±0.000 | 0.1717±0.000 | | C45: | **Probabilistic Forecasting w/ Regime Condition** | | | | | | | | | | |
...

Sheet ICML Table 1
A4: Model | B4: Overall MSE | C4: Overall MAE | D4: Complex MSE | E4: Complex MAE | F4: Stable MSE | G4: Stable MAE | H4: Oscillatory MSE | I4: Oscillatory MAE | J4: Monotonic MSE | K4: Monotonic MAE
A5: Point Forecasting
A6: DLinear | B6: 0.061 | C6: 0.174 | D6: 0.079 | E6: 0.188 | F6: 0.046 | G6: 0.154 | H6: 0.156 | I6: 0.29 | J6: 0.051 | K6: 0.176
A7: iTransformer | B7: 0.045 | C7: 0.1 | D7: 0.07 | E7: 0.138 | F7: 0.032 | G7: 0.072 | H7: 0.127 | I7: 0.233 | J7: 0.03 | K7: 0.1
A8: PatchTST | B8: 0.041 | C8: 0.095 | D8: 0.062 | E8: 0.133 | F8: 0.028 | G8: 0.07 | H8: 0.128 | I8: 0.233 | J8: 0.021 | K8: 0.085
A9: TimeMixer | B9: 0.051 | C9: 0.124 | D9: 0.07 | E9: 0.145 | F9: 0.038 | G9: 0.096 | H9: 0.112 | I9: 0.234 | J9: 0.053 | K9: 0.163
A10: TimeXer | B10: 0.043 | C10: 0.1 | D10: 0.069 | E10: 0.139 | F10: 0.03 | G10: 0.074 | H10: 0.123 | I10: 0.231 | J10: 0.025 | K10: 0.098
A11: SMamba | B11: 0.045 | C11: 0.105 | D11: 0.068 | E11: 0.141 | F11: 0.033 | G11: 0.078 | H11: 0.114 | I11: 0.228 | J11: 0.035 | K11: 0.115
A12: BiMamba4TS | B12: 0.045 | C12: 0.099 | D12: 0.07 | E12: 0.14 | F12: 0.031 | G12: 0.07 | H12: 0.125 | I12: 0.237 | J12: 0.03 | K12: 0.102
A13: NSformer | B13: 0.028 | C13: 0.079 | D13: 0.048 | E13: 0.116 | F13: 0.017 | G13: 0.055 | H13: 0.1 | I13: 0.221 | J13: 0.011 | K13: 0.053
A14: Probabilistic Forecasting w/o Regime Condition
A15: CSDI | B15: 0.099 | C15: 0.254 | D15: 0.1 | E15: 0.25 | F15: 0.103 | G15: 0.264 | H15: 0.137 | I15: 0.304 | J15: 0.053 | K15: 0.172
A16: TSDiff | B16: 0.042 | C16: 0.118 | D16: 0.058 | E16: 0.146 | F16: 0.03 | G16: 0.096 | H16: 0.124 | I16: 0.263 | J16: 0.023 | K16: 0.092
A17: TSFlow | B17: 0.026 | C17: 0.075 | D17: 0.044 | E17: 0.111 | F17: 0.017 | G17: 0.055 | H17: 0.088 | I17: 0.208 | J17: 0.008 | K17: 0.044
A18: Ours | B18: 0.023 | C18: 0.067 | D18: 0.039 | E18: 0.102 | F18: 0.015 | G18: 0.046 | H18: 0.081 | I18: 0.196 | J18: 0.008 | K18: 0.041
A19: Probabilistic Forecasting w/ Regime Condition
A20: CSDI† | B20: 0.076 | C20: 0.204 | D20: 0.1 | E20: 0.236 | F20: 0.072 | G20: 0.196 | H20: 0.105 | I20: 0.257 | J20: 0.06 | K20: 0.183
A21: TSDiff† | B21: 0.034 | C21: 0.109 | D21: 0.088 | E21: 0.201 | F21: 0.014 | G21: 0.068 | H21: 0.118 | I21: 0.292 | J21: 0.014 | K21: 0.078
A22: TSFlow† | B22: 0.016 | C22: 0.064 | D22: 0.039 | E22: 0.111 | F22: 0.008 | G22: 0.046 | H22: 0.044 | I22: 0.139 | J22: 0.008 | K22: 0.05
A23: Ours† | B23: 0.012 | C23: 0.044 | D23: 0.034 | E23: 0.096 | F23: 0.006 | G23: 0.027 | H23: 0.035 | I23: 0.111 | J23: 0.006 | K23: 0.033
A25: | Ours† | 0.0106±0.001 | 0.0470±0.001 | 0.0288±0.014 | 0.0919±0.028 | 0.0052±0.000 | 0.0307±0.001 | 0.0390±0.001 | 0.1321±0.002 | 0.0037±0.000 | 0.0335±0.001 |

Sheet Percentage Difference (% Off)
A1: Percentage Difference Comparison
A2: Green means my data has lower error
A4: Model | B4: Overall MSE | C4: Overall MAE | D4: Complex MSE | E4: Complex MAE | F4: Stable MSE | G4: Stable MAE | H4: Oscillatory MSE | I4: Oscillatory MAE | J4: Monotonic MSE | K4: Monotonic MAE
A5: Point Forecasting | M5: Error
A6: DLinear | B6: =('ICML Table 1'!B6 - 'Ben benchmark'!B6) / 'Ben benchmark'!B6 -> 0.0321489 | C6: =('ICML Table 1'!C6 - 'Ben benchmark'!C6) / 'Ben benchmark'!C6 -> 0.022326675 | D6: =('ICML Table 1'!D6 - 'Ben benchmark'!D6) / 'Ben benchmark'!D6 -> 0.14992722 | E6: =('ICML Table 1'!E6 - 'Ben benchmark'!E6) / 'Ben benchmark'!E6 -> 0.063950198 | F6: =('ICML Table 1'!F6 - 'Ben benchmark'!F6) / 'Ben benchmark'!F6 -> 0.079812207 | G6: =('ICML Table 1'!G6 - 'Ben benchmark'!G6) / 'Ben benchmark'!G6 -> 0.033557047 | H6: =('ICML Table 1'!H6 - 'Ben benchmark'!H6) / 'Ben benchmark'!H6 -> -0.13381455 | I6: =('ICML Table 1'!I6 - 'Ben benchmark'!I6) / 'Ben benchmark'!I6 -> -0.074960128 | ... K6: =('ICML Table 1'!K6 - 'Ben benchmark'!K6) / 'Ben benchmark'!K6 -> -0.029233315 | M6: {=AVERAGE(ABS(B6:K6))} -> 0.062169487
A7: iTransformer | B7: =('ICML Table 1'!B7 - 'Ben benchmark'!B7) / 'Ben benchmark'!B7 -> 0.8 | C7: =('ICML Table 1'!C7 - 'Ben benchmark'!C7) / 'Ben benchmark'!C7 -> 0.447178 | D7: =('ICML Table 1'!D7 - 'Ben benchmark'!D7) / 'Ben benchmark'!D7 -> 2.4313725 | E7: =('ICML Table 1'!E7 - 'Ben benchmark'!E7) / 'Ben benchmark'!E7 -> 1.3271501 | F7: =('ICML Table 1'!F7 - 'Ben benchmark'!F7) / 'Ben benchmark'!F7 -> 0.7679558 | G7: =('ICML Table 1'!G7 - 'Ben benchmark'!G7) / 'Ben benchmark'!G7 -> 0.32352941 | H7: =('ICML Table 1'!H7 - 'Ben benchmark'!H7) / 'Ben benchmark'!H7 -> 0.19025305 | I7: =('ICML Table 1'!I7 - 'Ben benchmark'!I7) / 'Ben benchmark'!I7 -> 0.089803555 | ... K7: =('ICML Table 1'!K7 - 'Ben benchmark'!K7) / 'Ben benchmark'!K7 -> 0.30890052 | M7: {=AVERAGE(ABS(B7:K7))} -> 0.73077646
A8: PatchTST | B8: =('ICML Table 1'!B8 - 'Ben benchmark'!B8) / 'Ben benchmark'!B8 -> 0.5530303 | C8: =('ICML Table 1'!C8 - 'Ben benchmark'!C8) / 'Ben benchmark'!C8 -> 0.31578947 | D8: =('ICML Table 1'!D8 - 'Ben benchmark'!D8) / 'Ben benchmark'!D8 -> 1.9951691 | E8: =('ICML Table 1'!E8 - 'Ben benchmark'!E8) / 'Ben benchmark'!E8 -> 1.1555916 | F8: =('ICML Table 1'!F8 - 'Ben benchmark'!F8) / 'Ben benchmark'!F8 -> 0.50537634 | G8: =('ICML Table 1'!G8 - 'Ben benchmark'!G8) / 'Ben benchmark'!G8 -> 0.25448029 | H8: =('ICML Table 1'!H8 - 'Ben benchmark'!H8) / 'Ben benchmark'!H8 -> 0.030595813 | I8: =('ICML Table 1'!I8 - 'Ben benchmark'!I8) / 'Ben benchmark'!I8 -> -0.019772823 | ... K8: =('ICML Table 1'!K8 - 'Ben benchmark'!K8) / 'Ben benchmark'!K8 -> 0.11256545 | M8: {=AVERAGE(ABS(B8:K8))} -> 0.51998562
A9: TimeMixer | B9: =('ICML Table 1'!B9 - 'Ben benchmark'!B9) / 'Ben benchmark'!B9 -> -0.064220183 | C9: =('ICML Table 1'!C9 - 'Ben benchmark'!C9) / 'Ben benchmark'!C9 -> -0.18205805 | D9: =('ICML Table 1'!D9 - 'Ben benchmark'!D9) / 'Ben benchmark'!D9 -> 0.69082126 | E9: =('ICML Table 1'!E9 - 'Ben benchmark'!E9) / 'Ben benchmark'!E9 -> 0.2741652 | F9: =('ICML Table 1'!F9 - 'Ben benchmark'!F9) / 'Ben benchmark'!F9 -> -0.23847695 | G9: =('ICML Table 1'!G9 - 'Ben benchmark'!G9) / 'Ben benchmark'!G9 -> -0.34381408 | H9: =('ICML Table 1'!H9 - 'Ben benchmark'!H9) / 'Ben benchmark'!H9 -> -0.013215859 | I9: =('ICML Table 1'!I9 - 'Ben benchmark'!I9) / 'Ben benchmark'!I9 -> -0.01432182 | ... K9: =('ICML Table 1'!K9 - 'Ben benchmark'!K9) / 'Ben benchmark'!K9 -> -0.21332046 | M9: {=AVERAGE(ABS(B9:K9))} -> 0.22729196
A10: TimeXer | B10: =('ICML Table 1'!B10 - 'Ben benchmark'!B10) / 'Ben benchmark'!B10 -> 1.160804 | C10: =('ICML Table 1'!C10 - 'Ben benchmark'!C10) / 'Ben benchmark'!C10 -> 0.61550889 | D10: =('ICML Table 1'!D10 - 'Ben benchmark'!D10) / 'Ben benchmark'!D10 -> 3.3670886 | E10: =('ICML Table 1'!E10 - 'Ben benchmark'!E10) / 'Ben benchmark'!E10 -> 1.8194726 | F10: =('ICML Table 1'!F10 - 'Ben benchmark'!F10) / 'Ben benchmark'!F10 -> 1.2900763 | G10: =('ICML Table 1'!G10 - 'Ben benchmark'!G10) / 'Ben benchmark'!G10 -> 0.55462185 | H10: =('ICML Table 1'!H10 - 'Ben benchmark'!H10) / 'Ben benchmark'!H10 -> 0.26283368 | I10: =('ICML Table 1'!I10 - 'Ben benchmark'!I10) / 'Ben benchmark'!I10 -> 0.13069016 | ... K10: =('ICML Table 1'!K10 - 'Ben benchmark'!K10) / 'Ben benchmark'!K10 -> 0.2962963 | M10: {=AVERAGE(ABS(B10:K10))} -> 1.0142129
A11: SMamba | B11: =('ICML Table 1'!B11 - 'Ben benchmark'!B11) / 'Ben benchmark'!B11 -> 0.38461538 | C11: =('ICML Table 1'!C11 - 'Ben benchmark'!C11) / 'Ben benchmark'!C11 -> 0.2195122 | D11: =('ICML Table 1'!D11 - 'Ben benchmark'!D11) / 'Ben benchmark'!D11 -> 1.0298507 | E11: =('ICML Table 1'!E11 - 'Ben benchmark'!E11) / 'Ben benchmark'!E11 -> 0.73218673 | F11: =('ICML Table 1'!F11 - 'Ben benchmark'!F11) / 'Ben benchmark'!F11 -> 0.43478261 | G11: =('ICML Table 1'!G11 - 'Ben benchmark'!G11) / 'Ben benchmark'!G11 -> 0.1589896 | H11: =('ICML Table 1'!H11 - 'Ben benchmark'!H11) / 'Ben benchmark'!H11 -> -0.010416667 | I11: =('ICML Table 1'!I11 - 'Ben benchmark'!I11) / 'Ben benchmark'!I11 -> 0.013783904 | ... K11: =('ICML Table 1'!K11 - 'Ben benchmark'!K11) / 'Ben benchmark'!K11 -> 0.02954342 | M11: {=AVERAGE(ABS(B11:K11))} -> 0.32082205
A12: BiMamba4TS | B12: =('ICML Table 1'!B12 - 'Ben benchmark'!B12) / 'Ben benchmark'!B12 -> 0.66666667 | C12: =('ICML Table 1'!C12 - 'Ben benchmark'!C12) / 'Ben benchmark'!C12 -> 0.33423181 | D12: =('ICML Table 1'!D12 - 'Ben benchmark'!D12) / 'Ben benchmark'!D12 -> 2.2110092 | E12: =('ICML Table 1'!E12 - 'Ben benchmark'!E12) / 'Ben benchmark'!E12 -> 1.2116904 | F12: =('ICML Table 1'!F12 - 'Ben benchmark'!F12) / 'Ben benchmark'!F12 -> 0.58974359 | G12: =('ICML Table 1'!G12 - 'Ben benchmark'!G12) / 'Ben benchmark'!G12 -> 0.21107266 | H12: =('ICML Table 1'!H12 - 'Ben benchmark'!H12) / 'Ben benchmark'!H12 -> 0.097453907 | I12: =('ICML Table 1'!I12 - 'Ben benchmark'!I12) / 'Ben benchmark'!I12 -> 0.031780583 | ... K12: =('ICML Table 1'!K12 - 'Ben benchmark'!K12) / 'Ben benchmark'!K12 -> 0.17919075 | M12: {=AVERAGE(ABS(B12:K12))} -> 0.58841909
A13: NSformer | B13: =('ICML Table 1'!B13 - 'Ben benchmark'!B13) / 'Ben benchmark'!B13 -> 0.7721519 | C13: =('ICML Table 1'!C13 - 'Ben benchmark'!C13) / 'Ben benchmark'!C13 -> 0.35972461 | D13: =('ICML Table 1'!D13 - 'Ben benchmark'!D13) / 'Ben benchmark'!D13 -> 2.6923077 | E13: =('ICML Table 1'!E13 - 'Ben benchmark'!E13) / 'Ben benchmark'!E13 -> 1.334004 | F13: =('ICML Table 1'!F13 - 'Ben benchmark'!F13) / 'Ben benchmark'!F13 -> 0.75257732 | G13: =('ICML Table 1'!G13 - 'Ben benchmark'!G13) / 'Ben benchmark'!G13 -> 0.21412804 | H13: =('ICML Table 1'!H13 - 'Ben benchmark'!H13) / 'Ben benchmark'!H13 -> 0.11111111 | I13: =('ICML Table 1'!I13 - 'Ben benchmark'!I13) / 'Ben benchmark'!I13 -> 0.065060241 | ... K13: =('ICML Table 1'!K13 - 'Ben benchmark'!K13) / 'Ben benchmark'!K13 -> 0.12288136 | M13: {=AVERAGE(ABS(B13:K13))} -> 0.72883531
A14: Probabilistic Forecasting w/o Regime Condition
A15: CSDI | B15: =('ICML Table 1'!B15 - 'Ben benchmark'!B15) / 'Ben benchmark'!B15 -> 0.38075314 | C15: =('ICML Table 1'!C15 - 'Ben benchmark'!C15) / 'Ben benchmark'!C15 -> 0.35250266 | D15: =('ICML Table 1'!D15 - 'Ben benchmark'!D15) / 'Ben benchmark'!D15 -> 0.953125 | E15: =('ICML Table 1'!E15 - 'Ben benchmark'!E15) / 'Ben benchmark'!E15 -> 0.64690382 | F15: =('ICML Table 1'!F15 - 'Ben benchmark'!F15) / 'Ben benchmark'!F15 -> 0.43854749 | G15: =('ICML Table 1'!G15 - 'Ben benchmark'!G15) / 'Ben benchmark'!G15 -> 0.39978791 | H15: =('ICML Table 1'!H15 - 'Ben benchmark'!H15) / 'Ben benchmark'!H15 -> -0.010830325 | I15: =('ICML Table 1'!I15 - 'Ben benchmark'!I15) / 'Ben benchmark'!I15 -> 0.063308849 | ... K15: =('ICML Table 1'!K15 - 'Ben benchmark'!K15) / 'Ben benchmark'!K15 -> -0.1106515 | M15: {=AVERAGE(ABS(B15:K15))} -> 0.36099318
A16: TSDiff | B16: =('ICML Table 1'!B16 - 'Ben benchmark'!B16) / 'Ben benchmark'!B16 -> -0.5221843 | C16: =('ICML Table 1'!C16 - 'Ben benchmark'!C16) / 'Ben benchmark'!C16 -> -0.26571251 | D16: =('ICML Table 1'!D16 - 'Ben benchmark'!D16) / 'Ben benchmark'!D16 -> -0.3078759 | E16: =('ICML Table 1'!E16 - 'Ben benchmark'!E16) / 'Ben benchmark'!E16 -> -0.0081521739 | F16: =('ICML Table 1'!F16 - 'Ben benchmark'!F16) / 'Ben benchmark'!F16 -> -0.63414634 | G16: =('ICML Table 1'!G16 - 'Ben benchmark'!G16) / 'Ben benchmark'!G16 -> -0.35135135 | H16: =('ICML Table 1'!H16 - 'Ben benchmark'!H16) / 'Ben benchmark'!H16 -> -0.24159021 | I16: =('ICML Table 1'!I16 - 'Ben benchmark'!I16) / 'Ben benchmark'!I16 -> -0.059706829 | ... K16: =('ICML Table 1'!K16 - 'Ben benchmark'!K16) / 'Ben benchmark'!K16 -> -0.49616648 | M16: {=AVERAGE(ABS(B16:K16))} -> 0.35968483
A17: TSFlow | B17: =('ICML Table 1'!B17 - 'Ben benchmark'!B17) / 'Ben benchmark'!B17 -> -0.037037037 | C17: =('ICML Table 1'!C17 - 'Ben benchmark'!C17) / 'Ben benchmark'!C17 -> 0.13122172 | D17: =('ICML Table 1'!D17 - 'Ben benchmark'!D17) / 'Ben benchmark'!D17 -> 0.77419355 | E17: =('ICML Table 1'!E17 - 'Ben benchmark'!E17) / 'Ben benchmark'!E17 -> 0.79032258 | F17: =('ICML Table 1'!F17 - 'Ben benchmark'!F17) / 'Ben benchmark'!F17 -> -0.011627907 | G17: =('ICML Table 1'!G17 - 'Ben benchmark'!G17) / 'Ben benchmark'!G17 -> 0.13168724 | H17: =('ICML Table 1'!H17 - 'Ben benchmark'!H17) / 'Ben benchmark'!H17 -> -0.37544358 | I17: =('ICML Table 1'!I17 - 'Ben benchmark'!I17) / 'Ben benchmark'!I17 -> -0.17623762 | ... K17: =('ICML Table 1'!K17 - 'Ben benchmark'!K17) / 'Ben benchmark'!K17 -> -0.12 | M17: {=AVERAGE(ABS(B17:K17))} -> 0.27930543
A18: Ours | B18: =('ICML Table 1'!B18 - 'Ben benchmark'!B18) / 'Ben benchmark'!B18 -> 0.11111111 | C18: =('ICML Table 1'!C18 - 'Ben benchmark'!C18) / 'Ben benchmark'!C18 -> -0.062937063 | D18: =('ICML Table 1'!D18 - 'Ben benchmark'!D18) / 'Ben benchmark'!D18 -> 0.96969697 | E18: =('ICML Table 1'!E18 - 'Ben benchmark'!E18) / 'Ben benchmark'!E18 -> 0.37651822 | F18: =('ICML Table 1'!F18 - 'Ben benchmark'!F18) / 'Ben benchmark'!F18 -> 0.19047619 | G18: =('ICML Table 1'!G18 - 'Ben benchmark'!G18) / 'Ben benchmark'!G18 -> -0.14018692 | H18: =('ICML Table 1'!H18 - 'Ben benchmark'!H18) / 'Ben benchmark'!H18 -> -0.27549195 | I18: =('ICML Table 1'!I18 - 'Ben benchmark'!I18) / 'Ben benchmark'!I18 -> -0.2172524 | ... K18: =('ICML Table 1'!K18 - 'Ben benchmark'!K18) / 'Ben benchmark'!K18 -> -0.12765957 | M18: {=AVERAGE(ABS(B18:K18))} -> 0.2647801
A19: Probabilistic Forecasting w/ Regime Condition
A20: CSDI† | B20: =('ICML Table 1'!B20 - 'Ben benchmark'!B20) / 'Ben benchmark'!B20 -> 0.33567663 | C20: =('ICML Table 1'!C20 - 'Ben benchmark'!C20) / 'Ben benchmark'!C20 -> 0.18673647 | D20: =('ICML Table 1'!D20 - 'Ben benchmark'!D20) / 'Ben benchmark'!D20 -> 0.96078431 | E20: =('ICML Table 1'!E20 - 'Ben benchmark'!E20) / 'Ben benchmark'!E20 -> 0.63208852 | F20: =('ICML Table 1'!F20 - 'Ben benchmark'!F20) / 'Ben benchmark'!F20 -> 0.29263914 | G20: =('ICML Table 1'!G20 - 'Ben benchmark'!G20) / 'Ben benchmark'!G20 -> 0.12 | H20: =('ICML Table 1'!H20 - 'Ben benchmark'!H20) / 'Ben benchmark'!H20 -> 0.10759494 | I20: =('ICML Table 1'!I20 - 'Ben benchmark'!I20) / 'Ben benchmark'!I20 -> 0.10490112 | ... K20: =('ICML Table 1'!K20 - 'Ben benchmark'!K20) / 'Ben benchmark'!K20 -> 0.068925234 | M20: {=AVERAGE(ABS(B20:K20))} -> 0.29881283
A21: TSDiff† | B21: =('ICML Table 1'!B21 - 'Ben benchmark'!B21) / 'Ben benchmark'!B21 -> -0.42176871 | C21: =('ICML Table 1'!C21 - 'Ben benchmark'!C21) / 'Ben benchmark'!C21 -> -0.26599327 | D21: =('ICML Table 1'!D21 - 'Ben benchmark'!D21) / 'Ben benchmark'!D21 -> 0.27351664 | E21: =('ICML Table 1'!E21 - 'Ben benchmark'!E21) / 'Ben benchmark'!E21 -> 0.5112782 | F21: =('ICML Table 1'!F21 - 'Ben benchmark'!F21) / 'Ben benchmark'!F21 -> -0.62962963 | G21: =('ICML Table 1'!G21 - 'Ben benchmark'!G21) / 'Ben benchmark'!G21 -> -0.46750196 | H21: =('ICML Table 1'!H21 - 'Ben benchmark'!H21) / 'Ben benchmark'!H21 -> -0.44885567 | I21: =('ICML Table 1'!I21 - 'Ben benchmark'!I21) / 'Ben benchmark'!I21 -> -0.1444477 | ... K21: =('ICML Table 1'!K21 - 'Ben benchmark'!K21) / 'Ben benchmark'!K21 -> -0.54571928 | M21: {=AVERAGE(ABS(B21:K21))} -> 0.44347384
A22: TSFlow† | B22: =('ICML Table 1'!B22 - 'Ben benchmark'!B22) / 'Ben benchmark'!B22 -> 0.045751634 | C22: =('ICML Table 1'!C22 - 'Ben benchmark'!C22) / 'Ben benchmark'!C22 -> 0.16363636 | D22: =('ICML Table 1'!D22 - 'Ben benchmark'!D22) / 'Ben benchmark'!D22 -> 0.76470588 | E22: =('ICML Table 1'!E22 - 'Ben benchmark'!E22) / 'Ben benchmark'!E22 -> 0.81669394 | F22: =('ICML Table 1'!F22 - 'Ben benchmark'!F22) / 'Ben benchmark'!F22 -> 0.038961039 | G22: =('ICML Table 1'!G22 - 'Ben benchmark'!G22) / 'Ben benchmark'!G22 -> 0.13580247 | H22: =('ICML Table 1'!H22 - 'Ben benchmark'!H22) / 'Ben benchmark'!H22 -> -0.38973648 | I22: =('ICML Table 1'!I22 - 'Ben benchmark'!I22) / 'Ben benchmark'!I22 -> -0.20887877 | ... K22: =('ICML Table 1'!K22 - 'Ben benchmark'!K22) / 'Ben benchmark'!K22 -> 0.1627907 | M22: {=AVERAGE(ABS(B22:K22))} -> 0.32084388
A23: Ours† | B23: =('ICML Table 1'!B23 - 'Ben benchmark'!B23) / 'Ben benchmark'!B23 -> 0.13207547 | C23: =('ICML Table 1'!C23 - 'Ben benchmark'!C23) / 'Ben benchmark'!C23 -> -0.063829787 | D23: =('ICML Table 1'!D23 - 'Ben benchmark'!D23) / 'Ben benchmark'!D23 -> 0.18055556 | E23: =('ICML Table 1'!E23 - 'Ben benchmark'!E23) / 'Ben benchmark'!E23 -> 0.044613711 | F23: =('ICML Table 1'!F23 - 'Ben benchmark'!F23) / 'Ben benchmark'!F23 -> 0.15384615 | G23: =('ICML Table 1'!G23 - 'Ben benchmark'!G23) / 'Ben benchmark'!G23 -> -0.12052117 | H23: =('ICML Table 1'!H23 - 'Ben benchmark'!H23) / 'Ben benchmark'!H23 -> -0.1025641 | I23: =('ICML Table 1'!I23 - 'Ben benchmark'!I23) / 'Ben benchmark'!I23 -> -0.15972748 | ... K23: =('ICML Table 1'!K23 - 'Ben benchmark'!K23) / 'Ben benchmark'!K23 -> -0.014925373 | M23: {=AVERAGE(ABS(B23:K23))} -> 0.15942804
A26: Average | B26: =AVERAGE(B5:B23) -> 0.27059843 | C26: =AVERAGE(C5:C23) -> 0.14423989 | D26: =AVERAGE(D5:D23) -> 1.1960155 | E26: =AVERAGE(E5:E23) -> 0.73302985 | F26: =AVERAGE(F5:F23) -> 0.25130709 | G26: =AVERAGE(G5:G23) -> 0.069642565 | H26: =AVERAGE(H5:H23) -> -0.075132307 | I26: =AVERAGE(I5:I23) -> -0.035998572 | ... K26: =AVERAGE(K5:K23) -> -0.023536391
A28: Theory for why mine is better (particularly for complex regime)
A29: Because DLinear is a linear model, it converges very quickly, so early stopping shouldn't affect it much. Paper uses early stopping with patience of 5 epochs
A30: Mine trained for full 500 epochs, but still performed worse in some cases due to overfitting?
